Workbook
Name SegmentaciónDeDatos_Finca: #N/A
Name SegmentaciónDeDatos_Finca1: #N/A
Name SegmentaciónDeDatos_Variedad: #N/A

Sheet PA_Gen
A1: Faenas | B1: Finca | C1: Variedad | D1: Jornales
A2: Riego | B2: Puente Alto | C2: Selma | D2: 20.649307
A3: Calicatas | B3: Puente Alto | C3: Selma | D3: 2
A4: Malezas Mochila | B4: Puente Alto | C4: Selma | D4: 20.660754
A5: Desmalezar manual | B5: Puente Alto | C5: Selma | D5: 4.1298615
A6: Mugrones | B6: Puente Alto | C6: Selma | D6: 23.333734
A7: Seguridad | B7: Puente Alto | C7: Selma | D7: 4.1298615
A8: Hormigas | B8: Puente Alto | C8: Selma | D8: 3.3038921
A9: Limpieza | B9: Puente Alto | C9: Selma | D9: 9.2994012
A10: Datos | B10: Puente Alto | C10: Selma | D10: 4.1298615
A11: Reparar Estructura | B11: Puente Alto | C11: Selma | D11: 6.6077608
A12: Tractorista Generales | B12: Puente Alto | C12: Selma | D12: 9.9116693
A13: Hoyar y Replantar | B13: Puente Alto | C13: Selma | D13: 3.5109269
... A49: Feriados | B49: Puente Alto | C49: Arizul | D49: 7.5849139

Sheet PA_Esp
A1: Faenas | B1: Finca | C1: Variedad | D1: Jornales
A2: Poda | B2: Puente Alto | C2: Selma | D2: 67.938182
A3: Atada | B3: Puente Alto | C3: Selma | D3: 45.292121
A4: Desbrote de troncos | B4: Puente Alto | C4: Selma | D4: 71.676923
A5: Acomodo de brotes | B5: Puente Alto | C5: Selma | D5: 31.06
A6: Desniete Deshoje | B6: Puente Alto | C6: Selma | D6: 0
A7: Desbrote con criterio de Poda | B7: Puente Alto | C7: Selma | D7: 18.636
A8: Raleo de Racimos | B8: Puente Alto | C8: Selma | D8: 0
A9: Tractorista Subsolado | B9: Puente Alto | C9: Selma | D9: 3.3038892
A10: Tractorista Triturado de sarmiento | B10: Puente Alto | C10: Selma | D10: 1.4454515
A11: Tractorista Cincelado | B11: Puente Alto | C11: Selma | D11: 0.61950668
A12: Tractorista Rastra | B12: Puente Alto | C12: Selma | D12: 13.009064
A13: Tractor Herbicida | B13: Puente Alto | C13: Selma | D13: 1.5488697
... A40: Tractor Atomizadora | B40: Puente Alto | C40: Arizul | D40: 15.212

Sheet CT_Gen
A1: Faenas | B1: Finca | C1: Jornales
A2: Riego | B2: Camino Truncado | C2: 543.99445
A3: Mantenimiento | B3: Camino Truncado | C3: 40
A4: Mangueras | B4: Camino Truncado | C4: 120
A5: Calicatas | B5: Camino Truncado | C5: 12.000612
A6: Malezas Mochila | B6: Camino Truncado | C6: 255.79565
A7: Desmalezar manual | B7: Camino Truncado | C7: 100
A8: Jardinería | B8: Camino Truncado | C8: 10
A9: Hormigas | B9: Camino Truncado | C9: 62.01695
A10: Limpieza | B10: Camino Truncado | C10: 32.999966
A11: Taller | B11: Camino Truncado | C11: 99.996601
A12: Datos | B12: Camino Truncado | C12: 75
A13: Reparar Estructura | B13: Camino Truncado | C13: 40
... A19: Feriados | B19: Camino Truncado | C19: 180
C20: =SUBTOTAL(109,CT_Gen[Jornales]) -> 2001.8096

Sheet CT_Esp
A1: Faenas | B1: Finca | C1: Variedad | D1: Jornales
A2: Poda | B2: Camino Truncado | C2: Flame | D2: 270.4452
A3: Atada | B3: Camino Truncado | C3: Flame | D3: 180.2968
A4: Desbrote de troncos | B4: Camino Truncado | C4: Flame | D4: 67.338
A5: Acomodo de brotes | B5: Camino Truncado | C5: Flame | D5: 0
A6: Desniete Deshoje | B6: Camino Truncado | C6: Flame | D6: 0
A7: Desbrote con criterio de Poda | B7: Camino Truncado | C7: Flame | D7: 48.098571
A8: Raleo de Racimos | B8: Camino Truncado | C8: Flame | D8: 67.338
A9: Tractorista Subsolado | B9: Camino Truncado | C9: Flame | D9: 10
A10: Tractorista Triturado de sarmiento | B10: Camino Truncado | C10: Flame | D10: 6.4999952
A11: Tractorista Cincelado | B11: Camino Truncado | C11: Flame | D11: 4.8800037
A12: Tractorista Rastra | B12: Camino Truncado | C12: Flame | D12: 12.990034
A13: Tractor Herbicida | B13: Camino Truncado | C13: Flame | D13: 20
... A66: Tractor Atomizadora | B66: Camino Truncado | C66: Superior | D66: 3.58
D67: =SUBTOTAL(109,CT_Esp[Jornales]) -> 2444.6877

Sheet LCH_Gen
A1: Faenas | B1: Finca | C1: Variedad | D1: Jornales
A2: Riego | B2: La Chimbera | C2: Flame | D2: 42.693236
A3: Mantenimiento | B3: La Chimbera | C3: Flame | D3: 23.244135
A4: Calicatas | B4: La Chimbera | C4: Flame | D4: 1.4231072
A5: Malezas Mochila | B5: La Chimbera | C5: Flame | D5: 45.065086
A6: Desmalezar manual | B6: La Chimbera | C6: Flame | D6: 11.384837
A7: Mugrones | B7: La Chimbera | C7: Flame | D7: 52.180557
A8: Seguridad | B8: La Chimbera | C8: Flame | D8: 5.6924288
A9: Hormigas | B9: La Chimbera | C9: Flame | D9: 8.7758325
A10: Limpieza | B10: La Chimbera | C10: Flame | D10: 21.356498
A11: Datos | B11: La Chimbera | C11: Flame | D11: 7.8278146
A12: Reparar Estructura | B12: La Chimbera | C12: Flame | D12: 14.711345
A13: Tractorista Generales | B13: La Chimbera | C13: Flame | D13: 21.356498
... A52: Feriados | B52: La Chimbera | C52: Arizul | D52: 8.459472

Sheet LHC_Esp
A1: Faenas | B1: Finca | C1: Variedad | D1: Jornales
A2: Poda | B2: La Chimbera | C2: Flame | D2: 236.4
A3: Atada | B3: La Chimbera | C3: Flame | D3: 157.6
A4: Desbrote de troncos | B4: La Chimbera | C4: Flame | D4: 151.38916
A5: Acomodo de brotes | B5: La Chimbera | C5: Flame | D5: 61.464
A6: Desniete Deshoje | B6: La Chimbera | C6: Flame | D6: 61.464
A7: Desbrote con criterio de Poda | B7: La Chimbera | C7: Flame | D7: 61.464
A8: Raleo de Racimos | B8: La Chimbera | C8: Flame | D8: 102.44
A9: Tractorista Subsolado | B9: La Chimbera | C9: Flame | D9: 9.0123167
A10: Tractorista Triturado de sarmiento | B10: La Chimbera | C10: Flame | D10: 2.3718453
A11: Tractorista Cincelado | B11: La Chimbera | C11: Flame | D11: 1.8982088
A12: Tractorista Rastra | B12: La Chimbera | C12: Flame | D12: 2.3718453
A13: Tractor Herbicida | B13: La Chimbera | C13: Flame | D13: 11.384858
... A40: Tractor Atomizadora | B40: La Chimbera | C40: Arizul | D40: 20.29807

Sheet EE_Esp
A1: Faenas | B1: Finca | C1: Variedad | D1: Año de plantación | E1: Jornales | F1: Txt ref
A2: Poda | B2: El Espejo I | C2: Flame | D2: 2019 | E2: 541.91667 | F2: =+EE_Esp[[#This Row],[Variedad]]&" "&EE_Esp[[#This Row],[Año de plantación]] -> Flame 2019
A3: Atada | B3: El Espejo I | C3: Flame | D3: 2019 | E3: 541.91667 | F3: =+EE_Esp[[#This Row],[Variedad]]&" "&EE_Esp[[#This Row],[Año de plantación]] -> Flame 2019
A4: Desbrote de troncos | B4: El Espejo I | C4: Flame | D4: 2019 | E4: 130.06 | F4: =+EE_Esp[[#This Row],[Variedad]]&" "&EE_Esp[[#This Row],[Año de plantación]] -> Flame 2019
A5: Acomodo de brotes | B5: El Espejo I | C5: Flame | D5: 2019 | E5: 130.06 | F5: =+EE_Esp[[#This Row],[Variedad]]&" "&EE_Esp[[#This Row],[Año de plantación]] -> Flame 2019
A6: Desniete Deshoje | B6: El Espejo I | C6: Flame | D6: 2019 | E6: 65.03 | F6: =+EE_Esp[[#This Row],[Variedad]]&" "&EE_Esp[[#This Row],[Año de plantación]] -> Flame 2019
A7: Desbrote con criterio de Poda | B7: El Espejo I | C7: Flame | D7: 2019 | E7: 130.06 | F7: =+EE_Esp[[#This Row],[Variedad]]&" "&EE_Esp[[#This Row],[Año de plantación]] -> Flame 2019
A8: Raleo de Racimos | B8: El Espejo I | C8: Flame | D8: 2019 | E8: 650.3 | F8: =+EE_Esp[[#This Row],[Variedad]]&" "&EE_Esp[[#This Row],[Año de plantación]] -> Flame 2019
A9: Tractorista Subsolado | B9: El Espejo I | C9: Flame | D9: 2019 | E9: 0.77644331 | F9: =+EE_Esp[[#This Row],[Variedad]]&" "&EE_Esp[[#This Row],[Año de plantación]] -> Flame 2019
A10: Tractor Herbicida | B10: El Espejo I | C10: Flame | D10: 2019 | E10: 8.597985 | F10: =+EE_Esp[[#This Row],[Variedad]]&" "&EE_Esp[[#This Row],[Año de plantación]] -> Flame 2019
A11: Tractor Atomizadora | B11: El Espejo I | C11: Flame | D11: 2019 | E11: 30.80105 | F11: =+EE_Esp[[#This Row],[Variedad]]&" "&EE_Esp[[#This Row],[Año de plantación]] -> Flame 2019
A12: Poda | B12: El Espejo I | C12: Flame | D12: 2020 | E12: 88.412522 | F12: =+EE_Esp[[#This Row],[Variedad]]&" "&EE_Esp[[#This Row],[Año de plantación]] -> Flame 2020
A13: Atada | B13: El Espejo I | C13: Flame | D13: 2020 | E13: 58.941682 | F13: =+EE_Esp[[#This Row],[Variedad]]&" "&EE_Esp[[#This Row],[Año de plantación]] -> Flame 2020
... A81: Tractor Atomizadora | B81: El Espejo III | C81: Selma | D81: 2021 | E81: 8.2914429 | F81: =+EE_Esp[[#This Row],[Variedad]]&" "&EE_Esp[[#This Row],[Año de plantación]] -> Selma 2021

Sheet EE_Gen
A1: Faenas | B1: Finca | C1: Variedad | D1: Jornales
A2: Riego | B2: El Espejo I | C2: Flame | D2: 573.64539
A3: Mantenimiento | B3: El Espejo I | C3: Flame | D3: 122.04135
A4: Mangueras | B4: El Espejo I | C4: Flame | D4: 87.430621
A5: Calicatas | B5: El Espejo I | C5: Flame | D5: 7.0091505
A6: Malezas Mochila | B6: El Espejo I | C6: Flame | D6: 151.25148
A7: Desmalezar manual | B7: El Espejo I | C7: Flame | D7: 260.74301
A8: Seguridad | B8: El Espejo I | C8: Flame | D8: 104.76836
A9: Hormigas | B9: El Espejo I | C9: Flame | D9: 36.890266
A10: Limpieza | B10: El Espejo I | C10: Flame | D10: 11.804888
A11: Taller | B11: El Espejo I | C11: Flame | D11: 320.44571
A12: Datos | B12: El Espejo I | C12: Flame | D12: 34.307913
A13: Reparar Estructura | B13: El Espejo I | C13: Flame | D13: 105.50596
... A127: Feriados | B127: El Espejo III | C127: Selma | D127: 5.9891737

Sheet Visualización Jornales EE III
A1: Detalle | B1: MES | C1: Valor | D1: Finca
A2: Contratados | B2: Mayo | C2: 1338.0034 | D2: El Espejo III
A3: Contratados | B3: Junio | C3: 7374.1011 | D3: El Espejo III
A4: Contratados | B4: Julio | C4: 7152.1865 | D4: El Espejo III
A5: Contratados | B5: Agosto | C5: 8830.8809 | D5: El Espejo III
A6: Contratados | B6: Septiembre | C6: 9637.7644 | D6: El Espejo III
A7: Contratados | B7: Octubre | C7: 12599.25 | D7: El Espejo III
A8: Contratados | B8: Noviembre | C8: 12799.175 | D8: El Espejo III
A9: Contratados | B9: Diciembre | C9: 12049.274 | D9: El Espejo III
A10: Contratados | B10: Enero | C10: 2132.5928 | D10: El Espejo III
A11: Contratados | B11: Febrero | C11: 9264.5315 | D11: El Espejo III
A12: Contratados | B12: Marzo | C12: 9599.4266 | D12: El Espejo III
A13: Contratados | B13: Abril | C13: 3307.664 | D13: El Espejo III
... A25: Combustible y Lubricantes | B25: Abril | C25: 0 | D25: El Espejo III

Sheet Visualización Jornales EE I y I
A1: Detalle | B1: MES | C1: Valor | D1: Finca
A2: Contratados | B2: Mayo | C2: 3183.9696 | D2: El Espejo I y II
A3: Contratados | B3: Junio | C3: 17547.723 | D3: El Espejo I y II
A4: Contratados | B4: Julio | C4: 17019.646 | D4: El Espejo I y II
A5: Contratados | B5: Agosto | C5: 21014.338 | D5: El Espejo I y II
A6: Contratados | B6: Septiembre | C6: 22934.433 | D6: El Espejo I y II
A7: Contratados | B7: Octubre | C7: 29981.709 | D7: El Espejo I y II
A8: Contratados | B8: Noviembre | C8: 30457.46 | D8: El Espejo I y II
A9: Contratados | B9: Diciembre | C9: 28672.964 | D9: El Espejo I y II
A10: Contratados | B10: Enero | C10: 5074.8081 | D10: El Espejo I y II
A11: Contratados | B11: Febrero | C11: 22046.272 | D11: El Espejo I y II
A12: Contratados | B12: Marzo | C12: 22843.202 | D12: El Espejo I y II
A13: Contratados | B13: Abril | C13: 7871.0573 | D13: El Espejo I y II
... A25: Combustible y Lubricantes | B25: Abril | C25: 0 | D25: El Espejo I y II

Sheet Visualización Jornales PA (2)
A1: Detalle | B1: MES | C1: Valor | D1: Finca
A2: Contratados | B2: Mayo | C2: 2832.4121 | D2: Puente Alto
A3: Contratados | B3: Junio | C3: 3124.2459 | D3: Puente Alto
A4: Contratados | B4: Julio | C4: 2762.1809 | D4: Puente Alto
A5: Contratados | B5: Agosto | C5: 4135.9623 | D5: Puente Alto
A6: Contratados | B6: Septiembre | C6: 661.23757 | D6: Puente Alto
A7: Contratados | B7: Octubre | C7: 4951.2246 | D7: Puente Alto
A8: Contratados | B8: Noviembre | C8: 2984.0684 | D8: Puente Alto
A9: Contratados | B9: Diciembre | C9: 2999.7045 | D9: Puente Alto
A10: Contratados | B10: Enero | C10: 522.38855 | D10: Puente Alto
A11: Contratados | B11: Febrero | C11: 1978.6718 | D11: Puente Alto
A12: Contratados | B12: Marzo | C12: 2422.1948 | D12: Puente Alto
A13: Contratados | B13: Abril | C13: 808.99269 | D13: Puente Alto
... A25: Combustible y Lubricantes | B25: Abril | C25: 411.24224 | D25: Puente Alto

Sheet Visualización Jornales LCH (2)
A1: Detalle | B1: MES | C1: Valor | D1: Finca
A2: Contratados | B2: Mayo | C2: 3785.7037 | D2: La Chimbera
A3: Contratados | B3: Junio | C3: 5446.9104 | D3: La Chimbera
A4: Contratados | B4: Julio | C4: 3802.7777 | D4: La Chimbera
A5: Contratados | B5: Agosto | C5: 4577.028 | D5: La Chimbera
A6: Contratados | B6: Septiembre | C6: 1278.1208 | D6: La Chimbera
A7: Contratados | B7: Octubre | C7: 3243.9384 | D7: La Chimbera
A8: Contratados | B8: Noviembre | C8: 930.3802 | D8: La Chimbera
A9: Contratados | B9: Diciembre | C9: 2468.7886 | D9: La Chimbera
A10: Contratados | B10: Enero | C10: 1347.7149 | D10: La Chimbera
A11: Contratados | B11: Febrero | C11: 5416.165 | D11: La Chimbera
A12: Contratados | B12: Marzo | C12: 5443.211 | D12: La Chimbera
A13: Contratados | B13: Abril | C13: 1549.8074 | D13: La Chimbera
... A25: Combustible y Lubricantes | B25: Abril | C25: 72.421926 | D25: La Chimbera

Sheet Visualización Jornales CT
A1: Jornal Presupuestado | B1: $ | C1: =+INDEX(Tabla2[Precio Jornal],MATCH(C$19,Tabla2[Mes],0)) -> 19319.2 | D1: =+INDEX(Tabla2[Precio Jornal],MATCH(D$19,Tabla2[Mes],0)) -> 19646 | E1: =+INDEX(Tabla2[Precio Jornal],MATCH(E$19,Tabla2[Mes],0)) -> 19976.6 | F1: =+INDEX(Tabla2[Precio Jornal],MATCH(F$19,Tabla2[Mes],0)) -> 20312.9 | G1: =+INDEX(Tabla2[Precio Jornal],MATCH(G$19,Tabla2[Mes],0)) -> 20654.9 | H1: =+INDEX(Tabla2[Precio Jornal],MATCH(H$19,Tabla2[Mes],0)) -> 21002.6 | I1: =+INDEX(Tabla2[Precio Jornal],MATCH(I$19,Tabla2[Mes],0)) -> 21357.9 | J1: =+INDEX(Tabla2[Precio Jornal],MATCH(J$19,Tabla2[Mes],0)) -> 21717 | ... N1: =+INDEX(Tabla2[Precio Jornal],MATCH(N$19,Tabla2[Mes],0)) -> 23218
A2: Días Laborales | C2: 23.5 | D2: 20.5 | E2: 24 | F2: 24 | G2: 23 | H2: 24.5 | I2: 22.5 | J2: 23 | K2: 24 | L2: 20.5 | M2: 23 | N2: 22
A3: Jornales Disponibles CT | B3: 11 | C3: =+$B3*C2 -> 258.5 | D3: =+$B3*D2 -> 225.5 | E3: =+$B3*E2 -> 264 | F3: =+$B3*F2 -> 264 | G3: =+$B3*G2 -> 253 | H3: =+$B3*H2 -> 269.5 | I3: =+$B3*I2 -> 247.5 | J3: =+$B3*J2 -> 253 | ... N3: =+$B3*N2 -> 242 | O3: cosecha | P3: secado | Q3: gral | R3: Jorn/Has
A4: Jornales Cosecha | B4: =+SUMIF(TablaGeneral[Finca],$A$18,TablaGeneral[Resumen Jornales totales de Cosecha]) -> 417.99975 | K4: =+B4*0.2 -> 83.599949 | L4: =+B4*0.4 -> 167.1999 | M4: =+B4*0.4 -> 167.1999 | O4: =SUM(C4:N4) -> 417.99975 | P4: =SUM(C5:N5) -> 849.9303 | Q4: =+O114 -> 4446.4973 | R4: =+(O4+P4+Q4)/SUMIFS(TablaGeneral[Has],TablaGeneral[Finca],A18) -> 86.524812
A5: Jornales Secado | B5: =+SUMIFS(TablaGeneral[Resumen Jornales totales de Secado],TablaGeneral[Finca],"Camino truncado")*0.75 -> 850.03374 | C5: =+$B5*C18 -> 116.97328 | D5: =+$B5*D18 -> 100.70988 | E5: =+$B5*E18 -> 0 | F5: =+$B5*F18 -> 0 | G5: =+$B5*G18 -> 8.1317003 | H5: =+$B5*H18 -> 0 | I5: =+$B5*I18 -> 0 | J5: =+$B5*J18 -> 2.7105668 | ... N5: =+$B5*N18 -> 127.81555 | Q5: =+Q4/65 -> 68.407651
A6: Jornales a contratar | B6: =SUM(C6:N6) -> 2694.9274 | C6: =+(C114+C4+C5)-C3 -> 165.52657 | D6: =+D114+D4+D5-D3 -> 464.34616 | E6: =+E114+E4+E5-E3 -> 322.53808 | F6: =+F114+F4+F5-F3 -> 461.67684 | G6: =+G114+G4+G5-G3 -> 111.58305 | H6: =+H114+H4+H5-H3 -> 119.34185 | I6: =+I114+I4+I5-I3 -> 151.51738 | J6: =+J114+J4+J5-J3 -> 98.338568 | K6: =+K114+K4+K5-K3 -> 69.297822 | ... N6: =+N114+N4+N5-N3 -> 110.78363
A7: Contratados CT $ | B7: =SUM(C7:N7) -> 56460377 | C7: =+C6*C1 -> 3197841 | D7: =+D6*D1 -> 9122544.7 | E7: =+E6*E1 -> 6443214.2 | F7: =+F6*F1 -> 9377995.5 | G7: =+G6*G1 -> 2304736.8 | H7: =+H6*H1 -> 2506489.2 | I7: =+I6*I1 -> 3236093.1 | J7: =+J6*J1 -> 2135618.7 | ... N7: =+N6*N1 -> 2572174.4 | P7: USD/Has
A8: Contratados CT USD | B8: =SUM(C8:N8) -> 47717.446 | C8: =+C7/INDEX(Tabla2[TC],MATCH(C19,Tabla2[Mes],0)) -> 2837.4809 | D8: =+D7/INDEX(Tabla2[TC],MATCH(D19,Tabla2[Mes],0)) -> 8014.3944 | E8: =+E7/INDEX(Tabla2[TC],MATCH(E19,Tabla2[Mes],0)) -> 5604.4875 | F8: =+F7/INDEX(Tabla2[TC],MATCH(F19,Tabla2[Mes],0)) -> 8076.4774 | G8: =+G7/INDEX(Tabla2[TC],MATCH(G19,Tabla2[Mes],0)) -> 1965.2234 | H8: =+H7/INDEX(Tabla2[TC],MATCH(H19,Tabla2[Mes],0)) -> 2116.0945 | I8: =+I7/INDEX(Tabla2[TC],MATCH(I19,Tabla2[Mes],0)) -> 2705.0098 | J8: =+J7/INDEX(Tabla2[TC],MATCH(J19,Tabla2[Mes],0)) -> 1767.4624 | ... N8: =+N7/INDEX(Tabla2[TC],MATCH(N19,Tabla2[Mes],0)) -> 2045.6973 | P8: =+B8/SUMIFS(TablaGeneral[Has],TablaGeneral[Finca],A18) -> 722.51213
A9: Combustible Litros Gen | B9: =SUM(C9:N9) -> 3758.3181 | C9: =+(SUM(C20:C25,C34:C39,C48:C53,C62:C67,C76:C81,C106)*11.5) -> 57.5 | D9: =+(SUM(D20:D25,D34:D39,D48:D53,D62:D67,D76:D81,D106)*11.5) -> 57.5 | E9: =+(SUM(E20:E25,E34:E39,E48:E53,E62:E67,E76:E81,E106)*11.5) -> 57.5 | F9: =+(SUM(F20:F25,F34:F39,F48:F53,F62:F67,F76:F81,F106)*11.5) -> 882.62509 | G9: =+(SUM(G20:G25,G34:G39,G48:G53,G62:G67,G76:G81,G106)*11.5) -> 710.36805 | H9: =+(SUM(H20:H25,H34:H39,H48:H53,H62:H67,H76:H81,H106)*11.5) -> 285.83255 | I9: =+(SUM(I20:I25,I34:I39,I48:I53,I62:I67,I76:I81,I106)*11.5) -> 512.86606 | J9: =+(SUM(J20:J25,J34:J39,J48:J53,J62:J67,J76:J81,J106)*11.5) -> 250.12478 | ... N9: =+(SUM(N20:N25,N34:N39,N48:N53,N62:N67,N76:N81,N106)*11.5) -> 316.13555
A10: Combustible Litros Sec | B10: =SUM(C10:N10) -> 8159.3309 | C10: =+(SUMIFS(TablaGeneral[Resumen Jornales totales de Secado],TablaGeneral[Finca],"Camino truncado"))*0.72*C18*10 -> 1122.9435 | D10: =+(SUMIFS(TablaGeneral[Resumen Jornales totales de Secado],TablaGeneral[Finca],"Camino truncado"))*0.72*D18*10 -> 966.81486 | E10: =+(SUMIFS(TablaGeneral[Resumen Jornales totales de Secado],TablaGeneral[Finca],"Camino truncado"))*0.72*E18*10 -> 0 | F10: =+(SUMIFS(TablaGeneral[Resumen Jornales totales de Secado],TablaGeneral[Finca],"Camino truncado"))*0.72*F18*10 -> 0 | G10: =+(SUMIFS(TablaGeneral[Resumen Jornales totales de Secado],TablaGeneral[Finca],"Camino truncado"))*0.72*G18*10 -> 78.064323 | H10: =+(SUMIFS(TablaGeneral[Resumen Jornales totales de Secado],TablaGeneral[Finca],"Camino truncado"))*0.72*H18*10 -> 0 | I10: =+(SUMIFS(TablaGeneral[Resumen Jornales totales de Secado],TablaGeneral[Finca],"Camino truncado"))*0.72*I18*10 -> 0 | J10: =+(SUMIFS(TablaGeneral[Resumen Jornales totales de Secado],TablaGeneral[Finca],"Camino truncado"))*0.72*J18*10 -> 26.021441 | ... N10: =+(SUMIFS(TablaGeneral[Resumen Jornales totales de Secado],TablaGeneral[Finca],"Camino truncado"))*0.72*N18*10 -> 1227.0293
A11: Combustible Litros Cos | B11: =SUM(C11:N11) -> 4179.9975 | K11: =+SUMIFS(TablaGeneral[Resumen Jornales totales de Cosecha],TablaGeneral[Finca],$A$18)*0.2*10 -> 835.99949 | L11: =+SUMIFS(TablaGeneral[Resumen Jornales totales de Cosecha],TablaGeneral[Finca],$A$18)*0.4*10 -> 1671.999 | M11: =+SUMIFS(TablaGeneral[Resumen Jornales totales de Cosecha],TablaGeneral[Finca],$A$18)*0.4*10 -> 1671.999
A12: Combustible Litros Tot | B12: =SUM(C12:N12) -> 16097.647 | C12: =SUM(C9:C11) -> 1180.4435 | D12: =SUM(D9:D11) -> 1024.3149 | E12: =SUM(E9:E11) -> 57.5 | F12: =SUM(F9:F11) -> 882.62509 | G12: =SUM(G9:G11) -> 788.43238 | H12: =SUM(H9:H11) -> 285.83255 | I12: =SUM(I9:I11) -> 512.86606 | J12: =SUM(J9:J11) -> 276.14622 | ... N12: =SUM(N9:N11) -> 1543.1648
A13: Lubricantes Litros Totales | B13: =SUM(C13:N13) -> 348.78234 | C13: =+(C12/100)+(C12/150)+(C12/200) -> 25.576276 | D13: =+(D12/100)+(D12/150)+(D12/200) -> 22.193489 | E13: =+(E12/100)+(E12/150)+(E12/200) -> 1.2458333 | F13: =+(F12/100)+(F12/150)+(F12/200) -> 19.123544 | G13: =+(G12/100)+(G12/150)+(G12/200) -> 17.082701 | H13: =+(H12/100)+(H12/150)+(H12/200) -> 6.1930387 | I13: =+(I12/100)+(I12/150)+(I12/200) -> 11.112098 | J13: =+(J12/100)+(J12/150)+(J12/200) -> 5.983168 | ... N13: =+(N12/100)+(N12/150)+(N12/200) -> 33.435238
A14: Combustible USD | B14: =SUM(C14:N14) -> 20019786 | C14: =+(INDEX(Tabla2[Combustible],MATCH(C19,Tabla2[Mes],0))*C12) -> 1363618.8 | D14: =+(INDEX(Tabla2[Combustible],MATCH(D19,Tabla2[Mes],0))*D12) -> 1195095.6 | E14: =+(INDEX(Tabla2[Combustible],MATCH(E19,Tabla2[Mes],0))*E12) -> 67757.656 | F14: =+(INDEX(Tabla2[Combustible],MATCH(F19,Tabla2[Mes],0))*F12) -> 1050480.9 | G14: =+(INDEX(Tabla2[Combustible],MATCH(G19,Tabla2[Mes],0))*G12) -> 947758.58 | H14: =+(INDEX(Tabla2[Combustible],MATCH(H19,Tabla2[Mes],0))*H12) -> 347029.46 | I14: =+(INDEX(Tabla2[Combustible],MATCH(I19,Tabla2[Mes],0))*I12) -> 628897.66 | J14: =+(INDEX(Tabla2[Combustible],MATCH(J19,Tabla2[Mes],0))*J12) -> 342008.18 | ... N14: =+(INDEX(Tabla2[Combustible],MATCH(N19,Tabla2[Mes],0))*N12) -> 1988818.8
A15: Lubricantes USD | B15: =SUM(C15:N15) -> 2390981 | C15: =+(INDEX(Tabla2[Lubricantes],MATCH(C19,Tabla2[Mes],0))*C13) -> 162858.22 | D15: =+(INDEX(Tabla2[Lubricantes],MATCH(D19,Tabla2[Mes],0))*D13) -> 142731.33 | E15: =+(INDEX(Tabla2[Lubricantes],MATCH(E19,Tabla2[Mes],0))*E13) -> 8092.3575 | F15: =+(INDEX(Tabla2[Lubricantes],MATCH(F19,Tabla2[Mes],0))*F13) -> 125459.88 | G15: =+(INDEX(Tabla2[Lubricantes],MATCH(G19,Tabla2[Mes],0))*G13) -> 113191.66 | H15: =+(INDEX(Tabla2[Lubricantes],MATCH(H19,Tabla2[Mes],0))*H13) -> 41446.038 | I15: =+(INDEX(Tabla2[Lubricantes],MATCH(I19,Tabla2[Mes],0))*I13) -> 75109.81 | J15: =+(INDEX(Tabla2[Lubricantes],MATCH(J19,Tabla2[Mes],0))*J13) -> 40846.343 | ... N15: =+(INDEX(Tabla2[Lubricantes],MATCH(N19,Tabla2[Mes],0))*N13) -> 237526.4
A16: Combustible Pesos | B16: =SUM(C16:N16) -> 6983040.5 | C16: =+(C9*INDEX(Tabla2[Combustible],MATCH(C19,Tabla2[Mes],0)))+(C13*INDEX(Tabla2[Lubricantes],MATCH(C19,Tabla2[Mes],0))) -> 229280.78 | D16: =+(D9*INDEX(Tabla2[Combustible],MATCH(D19,Tabla2[Mes],0)))+(D13*INDEX(Tabla2[Lubricantes],MATCH(D19,Tabla2[Mes],0))) -> 209818.12 | E16: =+(E9*INDEX(Tabla2[Combustible],MATCH(E19,Tabla2[Mes],0)))+(E13*INDEX(Tabla2[Lubricantes],MATCH(E19,Tabla2[Mes],0))) -> 75850.013 | F16: =+(F9*INDEX(Tabla2[Combustible],MATCH(F19,Tabla2[Mes],0)))+(F13*INDEX(Tabla2[Lubricantes],MATCH(F19,Tabla2[Mes],0))) -> 1175940.8 | G16: =+(G9*INDEX(Tabla2[Combustible],MATCH(G19,Tabla2[Mes],0)))+(G13*INDEX(Tabla2[Lubricantes],MATCH(G19,Tabla2[Mes],0))) -> 967110.7 | H16: =+(H9*INDEX(Tabla2[Combustible],MATCH(H19,Tabla2[Mes],0)))+(H13*INDEX(Tabla2[Lubricantes],MATCH(H19,Tabla2[Mes],0))) -> 388475.5 | I16: =+(I9*INDEX(Tabla2[Combustible],MATCH(I19,Tabla2[Mes],0)))+(I13*INDEX(Tabla2[Lubricantes],MATCH(I19,Tabla2[Mes],0))) -> 704007.47 | J16: =+(J9*INDEX(Tabla2[Combustible],MATCH(J19,Tabla2[Mes],0)))+(J13*INDEX(Tabla2[Lubricantes],MATCH(J19,Tabla2[Mes],0))) -> 350626.87 | ... N16: =+(N9*INDEX(Tabla2[Combustible],MATCH(N19,Tabla2[Mes],0)))+(N13*INDEX(Tabla2[Lubricantes],MATCH(N19,Tabla2[Mes],0))) -> 644959.43
A17: Combustibles USD | B17: =SUM(C17:N17) -> 14293.181 | C17: =+INDEX(Tabla2[TC],MATCH(C19,Tabla2[Mes],0)) -> 1127 | D17: =+INDEX(Tabla2[TC],MATCH(D19,Tabla2[Mes],0)) -> 1138.27 | E17: =+INDEX(Tabla2[TC],MATCH(E19,Tabla2[Mes],0)) -> 1149.6527 | F17: =+INDEX(Tabla2[TC],MATCH(F19,Tabla2[Mes],0)) -> 1161.1492 | G17: =+INDEX(Tabla2[TC],MATCH(G19,Tabla2[Mes],0)) -> 1172.7607 | H17: =+INDEX(Tabla2[TC],MATCH(H19,Tabla2[Mes],0)) -> 1184.4883 | I17: =+INDEX(Tabla2[TC],MATCH(I19,Tabla2[Mes],0)) -> 1196.3332 | J17: =+INDEX(Tabla2[TC],MATCH(J19,Tabla2[Mes],0)) -> 1208.2965 | ... N17: =+INDEX(Tabla2[TC],MATCH(N19,Tabla2[Mes],0)) -> 1257.3582 | O17: =SUM(C17:N17)/SUMIFS(TablaGeneral[Has],TablaGeneral[Finca],A18) -> 216.41972
A18: Camino Truncado | B18: Jorn | C18: 0.13761016 | D18: 0.11847751 | E18: 0 | F18: 0 | G18: 0.0095663265 | H18: 0 | I18: 0 | J18: 0.0031887755 | K18: 0.07903824 | L18: 0.25998661 | M18: 0.24164543 | N18: 0.15036527
A19: Flame | B19: 715.20669 | C19: Mayo | D19: Junio | E19: Julio | F19: Agosto | G19: Septiembre | H19: Octubre | I19: Noviembre | J19: Diciembre | K19: Enero | L19: Febrero | M19: Marzo | N19: Abril
A20: Tractorista Subsolado | B20: 10 | F20: =+B20 -> 10
A21: Tractorista Triturado de sarmiento | B21: 6.4999952 | F21: =+B21 -> 6.4999952
A22: Tractorista Cincelado | B22: 4.8800037 | F22: =+B22 -> 4.8800037
A23: Tractorista Rastra | B23: 12.990034 | G23: =+B23/2 -> 6.4950172 | N23: =+B23/2 -> 6.4950172
A24: Tractor Atomizadora | B24: 27.320085 | G24: =+B24*0.45 -> 12.294038 | I24: =+B24*0.275 -> 7.5130235 | L24: =+B24*0.275 -> 7.5130235
A25: Tractor Herbicida | B25: 20 | H25: =+B25/4 -> 5 | I25: =+B25/4 -> 5 | J25: =+B25/4 -> 5 | L25: =+B25/4 -> 5
A26: Poda | B26: 270.4452 | D26: =+B26/3 -> 90.148401 | E26: =+B26/3 -> 90.148401 | F26: =+B26/3 -> 90.148401
A27: Atada | B27: 180.2968 | D27: =+B27/3 -> 60.098934 | E27: =+B27/3 -> 60.098934 | F27: =+B27/3 -> 60.098934
A28: Acomodo de brotes | B28: 0 | I28: =+B28 -> 0
A29: Desbrote de troncos | B29: 67.338 | H29: =+B29/2 -> 33.669 | J29: =+B29/2 -> 33.669
A30: Raleo de Racimos | B30: 67.338 | I30: =+B30 -> 67.338
A31: Desniete Deshoje | B31: 0
A32: Desbrote con criterio de Poda | B32: 48.098571 | H32: =+B32 -> 48.098571
A33: Fiesta | B33: 637.1396 | C33: =+SUM(C20:C32) -> 0 | D33: =+SUM(D20:D32) -> 150.24733 | E33: =+SUM(E20:E32) -> 150.24733 | F33: =+SUM(F20:F32) -> 171.62733 | G33: =+SUM(G20:G32) -> 18.789056 | H33: =+SUM(H20:H32) -> 86.767571 | I33: =+SUM(I20:I32) -> 79.851023 | J33: =+SUM(J20:J32) -> 38.669 | ... N33: =+SUM(N20:N32) -> 6.4950172
A34: Tractorista Subsolado | B34: 7.9000004 | F34: =+B34 -> 7.9000004
A35: Tractorista Triturado de sarmiento | B35: 5.299995 | F35: =+B35 -> 5.299995
A36: Tractorista Cincelado | B36: 3.9600031 | F36: =+B36 -> 3.9600031
A37: Tractorista Rastra | B37: 5.2800042 | G37: =+B37/2 -> 2.6400021 | N37: =+B37/2 -> 2.6400021
A38: Tractor Atomizadora | B38: 19.000093 | G38: =+B38*0.45 -> 8.550042 | I38: =+B38*0.275 -> 5.2250257 | L38: =+B38*0.275 -> 5.2250257
A39: Tractor Herbicida | B39: 15.999976 | H39: =+B39/4 -> 3.9999939 | I39: =+B39/4 -> 3.9999939 | J39: =+B39/4 -> 3.9999939 | L39: =+B39/4 -> 3.9999939
A40: Poda | B40: 223.53909 | D40: =+B40/3 -> 74.51303 | E40: =+B40/3 -> 74.51303 | F40: =+B40/3 -> 74.51303
...

Sheet Hoja1
A3: Suma de Jornales | B3: Etiquetas de columna
A4: Etiquetas de fila | B4: Camino Truncado | C4: El Espejo I | D4: El Espejo II | E4: El Espejo III | F4: La Chimbera | G4: Puente Alto | H4: Total general
A5: Camino Truncado | B5: 1233.3781 | H5: 1233.3781
A6: Colocación de malla | B6: 86.736597 | H6: 86.736597
A7: Dar vuelta la pasa | B7: 108.42095 | H7: 108.42095
A8: Descarga y carga de bines con Autoelevador | B8: 63.606681 | H8: 63.606681
A9: Desparramado de uva | B9: 140.94674 | H9: 140.94674
A10: Levantar pasa | B10: 165.54326 | H10: 165.54326
A11: Limpieza de secadero | B11: 10.842095 | H11: 10.842095
A12: Recolección de malla | B12: 86.736597 | H12: 86.736597
A13: Sereno | B13: 325.26164 | H13: 325.26164
A14: Tractor Cincelado de piedras | B14: 7.2280409 | H14: 7.2280409
A15: Tractor con acoplado | B15: 99.999823 | H15: 99.999823
A16: Tractor Descarga y carga de bines con tracto elevador | B16: 67.220813 | H16: 67.220813
A17: Tractor Volcado de bins | B17: 70.834914 | H17: 70.834914
A18: Grupo1 | C18: 279.95253 | D18: 44.811986 | H18: 324.76451
A19: Colocación de malla | C19: 12.023134 | H19: 12.023134
A20: Dar vuelta la pasa | C20: 24.254997 | H20: 24.254997
A21: Descarga y carga de bines con Autoelevador | C21: 6.2188557 | H21: 6.2188557
A22: Desparramado de uva | C22: 40.423975 | H22: 40.423975
A23: Levantar pasa | C23: 30.265184 | H23: 30.265184
A24: Limpieza de secadero | C24: 4.5604924 | H24: 4.5604924
A25: Recolección de malla | C25: 12.023134 | H25: 12.023134
A26: Sereno | C26: 80.24226 | H26: 80.24226
A27: Tractor con acoplado | C27: 43.188017 | D27: 44.811986 | H27: 88.000002
A28: Tractor Descarga y carga de bines con tracto elevador | C28: 6.6335363 | H28: 6.6335363
A29: Tractor Volcado de bins | C29: 20.118945 | H29: 20.118945
A30: El Espejo III | E30: 945.39835 | H30: 945.39835
A31: Colocación de malla | E31: 45.976964 | H31: 45.976964
A32: Dar vuelta la pasa | E32: 92.75212 | H32: 92.75212
A33: Descarga y carga de bines con Autoelevador | E33: 23.781164 | H33: 23.781164
A34: Desparramado de uva | E34: 154.58297 | H34: 154.58297
A35: Levantar pasa | E35: 115.73533 | H35: 115.73533
A36: Limpieza de secadero | E36: 17.439513 | H36: 17.439513
A37: Recolección de malla | E37: 45.976964 | H37: 45.976964
A38: Sereno | E38: 306.84975 | H38: 306.84975
A39: Tractor con acoplado | E39: 40.00098 | H39: 40.00098
A40: Tractor Descarga y carga de bines con tracto elevador | E40: 25.366919 | H40: 25.366919
A41: Tractor Volcado de bins | E41: 76.935685 | H41: 76.935685
A42: La Chimbera | F42: 315.0478 | H42: 315.0478
...

Sheet Visualización Jornales PA
A1: Jornal Presupuestado | B1: $ | C1: =+INDEX(Tabla2[Precio Jornal],MATCH(C$19,Tabla2[Mes],0)) -> 19319.2 | D1: =+INDEX(Tabla2[Precio Jornal],MATCH(D$19,Tabla2[Mes],0)) -> 19646 | E1: =+INDEX(Tabla2[Precio Jornal],MATCH(E$19,Tabla2[Mes],0)) -> 19976.6 | F1: =+INDEX(Tabla2[Precio Jornal],MATCH(F$19,Tabla2[Mes],0)) -> 20312.9 | G1: =+INDEX(Tabla2[Precio Jornal],MATCH(G$19,Tabla2[Mes],0)) -> 20654.9 | H1: =+INDEX(Tabla2[Precio Jornal],MATCH(H$19,Tabla2[Mes],0)) -> 21002.6 | I1: =+INDEX(Tabla2[Precio Jornal],MATCH(I$19,Tabla2[Mes],0)) -> 21357.9 | J1: =+INDEX(Tabla2[Precio Jornal],MATCH(J$19,Tabla2[Mes],0)) -> 21717 | ... N1: =+INDEX(Tabla2[Precio Jornal],MATCH(N$19,Tabla2[Mes],0)) -> 23218
A2: Días Laborales | C2: 23.5 | D2: 20.5 | E2: 24 | F2: 24 | G2: 23 | H2: 24.5 | I2: 22.5 | J2: 23 | K2: 24 | L2: 20.5 | M2: 23 | N2: 22
A3: Jornales Disponibles PA | B3: 2 | C3: =+$B3*C2 -> 47 | D3: =+$B3*D2 -> 41 | E3: =+$B3*E2 -> 48 | F3: =+$B3*F2 -> 48 | G3: =+$B3*G2 -> 46 | H3: =+$B3*H2 -> 49 | I3: =+$B3*I2 -> 45 | J3: =+$B3*J2 -> 46 | ... N3: =+$B3*N2 -> 44 | O3: cosecha | P3: secado | Q3: gral | R3: Jorn/Has
A4: Jornales Cosecha | B4: =+SUMIFS(TablaGeneral[Anotador],TablaGeneral[Finca],A18)+SUMIFS(TablaGeneral[Tracto elevador],TablaGeneral[Finca],A18)+SUMIFS(TablaGeneral[Tractor con uñas],TablaGeneral[Finca],A18)+SUMIFS(TablaGeneral[Lavar Bines],TablaGeneral[Finca],A18)+SUMIFS(TablaGeneral[Tractor con acoplado],TablaGeneral[Finca],A18) -> 165.00433 | K4: =+B4*0.2 -> 33.000866 | L4: =+B4*0.4 -> 66.001732 | M4: =+B4*0.4 -> 66.001732 | O4: =SUM(C4:N4) -> 165.00433 | P4: =SUM(C5:N5) -> 32.4141 | Q4: =+O84 -> 1968.1007 | R4: =+(O4+P4+Q4)/SUMIFS(TablaGeneral[Has],TablaGeneral[Finca],A18) -> 80.863299 | S4: =+Q4/SUMIFS(TablaGeneral[Has],TablaGeneral[Finca],A18) -> 73.491439
A5: Jornales Secado | B5: =+SUMIFS(TablaGeneral[Resumen Jornales totales de Secado],TablaGeneral[Finca],"Puente Alto")*0.28 -> 32.418045 | C5: =+$B5*C18 -> 4.4610524 | D5: =+$B5*D18 -> 3.8408092 | E5: =+$B5*E18 -> 0 | F5: =+$B5*F18 -> 0 | G5: =+$B5*G18 -> 0.3101216 | H5: =+$B5*H18 -> 0 | I5: =+$B5*I18 -> 0 | J5: =+$B5*J18 -> 0.10337387 | ... N5: =+$B5*N18 -> 4.8745479 | Q5: =+Q4/27 -> 72.892619
A6: Jornales a contratar | B6: =SUM(C6:N6) -> 1616.5192 | C6: =+(C5+C4+C84)-C3 -> 152.94445 | D6: =+(D5+D4+D84)-D3 -> 170.43756 | E6: =+(E5+E4+E84)-E3 -> 158.96342 | F6: =+(F5+F4+F84)-F3 -> 236.42461 | G6: =+(G5+G4+G84)-G3 -> 36.690161 | H6: =+(H5+H4+H84)-H3 -> 279.23532 | I6: =+(I5+I4+I84)-I3 -> 167.14846 | J6: =+(J5+J4+J84)-J3 -> 166.61369 | ... N6: =+(N5+N4+N84)-N3 -> 30.385295
A7: Contratados PA $ | B7: =SUM(C7:N7) -> 33719119 | C7: =+C6*C1 -> 2954764.3 | D7: =+D6*D1 -> 3348416.3 | E7: =+E6*E1 -> 3175548.7 | F7: =+F6*F1 -> 4802469.4 | G7: =+G6*G1 -> 757831.61 | H7: =+H6*H1 -> 5864667.7 | I7: =+I6*I1 -> 3569940.1 | J7: =+J6*J1 -> 3618349.5 | ... N7: =+N6*N1 -> 705485.77 | P7: USD/Has
A8: Contratados PA USD | B8: =SUM(C8:N8) -> 28575.367 | C8: =+C7/INDEX(Tabla2[TC],MATCH(C19,Tabla2[Mes],0)) -> 2621.7962 | D8: =+D7/INDEX(Tabla2[TC],MATCH(D19,Tabla2[Mes],0)) -> 2941.6714 | E8: =+E7/INDEX(Tabla2[TC],MATCH(E19,Tabla2[Mes],0)) -> 2762.1809 | F8: =+F7/INDEX(Tabla2[TC],MATCH(F19,Tabla2[Mes],0)) -> 4135.9623 | G8: =+G7/INDEX(Tabla2[TC],MATCH(G19,Tabla2[Mes],0)) -> 646.19458 | H8: =+H7/INDEX(Tabla2[TC],MATCH(H19,Tabla2[Mes],0)) -> 4951.2246 | I8: =+I7/INDEX(Tabla2[TC],MATCH(I19,Tabla2[Mes],0)) -> 2984.0684 | J8: =+J7/INDEX(Tabla2[TC],MATCH(J19,Tabla2[Mes],0)) -> 2994.5873 | ... N8: =+N7/INDEX(Tabla2[TC],MATCH(N19,Tabla2[Mes],0)) -> 561.08574 | P8: =+B8/SUMIFS(TablaGeneral[Has],TablaGeneral[Finca],A18) -> 1067.0413
A9: Combustible Litros Gen | B9: =SUM(C9:N9) -> 1535.0073 | C9: =+(SUM(C20:C25,C34:C39,C48:C53,C74)*7.5) -> 30.000005 | D9: =+(SUM(D20:D25,D34:D39,D48:D53,D74)*7.5) -> 30.000005 | E9: =+(SUM(E20:E25,E34:E39,E48:E53,E74)*7.5) -> 30.000005 | F9: =+(SUM(F20:F25,F34:F39,F48:F53,F74)*7.5) -> 225.001 | G9: =+(SUM(G20:G25,G34:G39,G48:G53,G74)*7.5) -> 266.25001 | H9: =+(SUM(H20:H25,H34:H39,H48:H53,H74)*7.5) -> 247.12656 | I9: =+(SUM(I20:I25,I34:I39,I48:I53,I74)*7.5) -> 168.15781 | J9: =+(SUM(J20:J25,J34:J39,J48:J53,J74)*7.5) -> 44.064064 | ... N9: =+(SUM(N20:N25,N34:N39,N48:N53,N74)*7.5) -> 266.25001
A10: Combustible Litros Sec | B10: =SUM(C10:N10) -> 324.141 | C10: =+(SUMIFS(TablaGeneral[Resumen Jornales totales de Secado],TablaGeneral[Finca],"Puente alto"))*0.28*C18*10 -> 44.610524 | D10: =+(SUMIFS(TablaGeneral[Resumen Jornales totales de Secado],TablaGeneral[Finca],"Puente alto"))*0.28*D18*10 -> 38.408092 | E10: =+(SUMIFS(TablaGeneral[Resumen Jornales totales de Secado],TablaGeneral[Finca],"Puente alto"))*0.28*E18*10 -> 0 | F10: =+(SUMIFS(TablaGeneral[Resumen Jornales totales de Secado],TablaGeneral[Finca],"Puente alto"))*0.28*F18*10 -> 0 | G10: =+(SUMIFS(TablaGeneral[Resumen Jornales totales de Secado],TablaGeneral[Finca],"Puente alto"))*0.28*G18*10 -> 3.101216 | H10: =+(SUMIFS(TablaGeneral[Resumen Jornales totales de Secado],TablaGeneral[Finca],"Puente alto"))*0.28*H18*10 -> 0 | I10: =+(SUMIFS(TablaGeneral[Resumen Jornales totales de Secado],TablaGeneral[Finca],"Puente alto"))*0.28*I18*10 -> 0 | J10: =+(SUMIFS(TablaGeneral[Resumen Jornales totales de Secado],TablaGeneral[Finca],"Puente alto"))*0.28*J18*10 -> 1.0337387 | ... N10: =+(SUMIFS(TablaGeneral[Resumen Jornales totales de Secado],TablaGeneral[Finca],"Puente alto"))*0.28*N18*10 -> 48.745479
A11: Combustible Litros Cos | B11: =SUM(C11:N11) -> 960.10638 | K11: =+(SUMIFS(TablaGeneral[Tracto elevador],TablaGeneral[Finca],A18)+SUMIFS(TablaGeneral[Tractor con uñas],TablaGeneral[Finca],A18)+SUMIFS(TablaGeneral[Tractor con acoplado],TablaGeneral[Finca],A18))*0.2*10 -> 192.02128 | L11: =+(SUMIFS(TablaGeneral[Tracto elevador],TablaGeneral[Finca],A18)+SUMIFS(TablaGeneral[Tractor con uñas],TablaGeneral[Finca],A18)+SUMIFS(TablaGeneral[Tractor con acoplado],TablaGeneral[Finca],A18))*0.4*10 -> 384.04255 | M11: =+(SUMIFS(TablaGeneral[Tracto elevador],TablaGeneral[Finca],A18)+SUMIFS(TablaGeneral[Tractor con uñas],TablaGeneral[Finca],A18)+SUMIFS(TablaGeneral[Tractor con acoplado],TablaGeneral[Finca],A18))*0.4*10 -> 384.04255
A12: Combustible Litros Tot | B12: =SUM(C12:N12) -> 2819.2547 | C12: =SUM(C9:C11) -> 74.61053 | D12: =SUM(D9:D11) -> 68.408098 | E12: =SUM(E9:E11) -> 30.000005 | F12: =SUM(F9:F11) -> 225.001 | G12: =SUM(G9:G11) -> 269.35122 | H12: =SUM(H9:H11) -> 247.12656 | I12: =SUM(I9:I11) -> 168.15781 | J12: =SUM(J9:J11) -> 45.097802 | ... N12: =SUM(N9:N11) -> 314.99548
A13: Lubricantes Litros Totales | B13: =SUM(C13:N13) -> 61.083851 | C13: =+(C12/100)+(C12/150)+(C12/200) -> 1.6165615 | D13: =+(D12/100)+(D12/150)+(D12/200) -> 1.4821754 | E13: =+(E12/100)+(E12/150)+(E12/200) -> 0.65000012 | F13: =+(F12/100)+(F12/150)+(F12/200) -> 4.8750217 | G13: =+(G12/100)+(G12/150)+(G12/200) -> 5.8359431 | H13: =+(H12/100)+(H12/150)+(H12/200) -> 5.3544089 | I13: =+(I12/100)+(I12/150)+(I12/200) -> 3.6434193 | J13: =+(J12/100)+(J12/150)+(J12/200) -> 0.97711905 | ... N13: =+(N12/100)+(N12/150)+(N12/200) -> 6.8249022
A14: Combustible USD | B14: =SUM(C14:N14) -> 3503180.5 | C14: =+(INDEX(Tabla2[Combustible],MATCH(C19,Tabla2[Mes],0))*C12) -> 86188.218 | D14: =+(INDEX(Tabla2[Combustible],MATCH(D19,Tabla2[Mes],0))*D12) -> 79813.557 | E14: =+(INDEX(Tabla2[Combustible],MATCH(E19,Tabla2[Mes],0))*E12) -> 35351.827 | F14: =+(INDEX(Tabla2[Combustible],MATCH(F19,Tabla2[Mes],0))*F12) -> 267791.23 | G14: =+(INDEX(Tabla2[Combustible],MATCH(G19,Tabla2[Mes],0))*G12) -> 323781.65 | H14: =+(INDEX(Tabla2[Combustible],MATCH(H19,Tabla2[Mes],0))*H12) -> 300036.49 | I14: =+(INDEX(Tabla2[Combustible],MATCH(I19,Tabla2[Mes],0))*I12) -> 206202.1 | J14: =+(INDEX(Tabla2[Combustible],MATCH(J19,Tabla2[Mes],0))*J12) -> 55853.807 | ... N14: =+(INDEX(Tabla2[Combustible],MATCH(N19,Tabla2[Mes],0))*N12) -> 405963.72 | P14: =+(B14+B15)/SUMIFS(TablaGeneral[Has],TablaGeneral[Finca],A18) -> 146436.46
A15: Lubricantes USD | B15: =SUM(C15:N15) -> 418387.98 | C15: =+(INDEX(Tabla2[Lubricantes],MATCH(C19,Tabla2[Mes],0))*C13) -> 10293.536 | D15: =+(INDEX(Tabla2[Lubricantes],MATCH(D19,Tabla2[Mes],0))*D13) -> 9532.2045 | E15: =+(INDEX(Tabla2[Lubricantes],MATCH(E19,Tabla2[Mes],0))*E13) -> 4222.1003 | F15: =+(INDEX(Tabla2[Lubricantes],MATCH(F19,Tabla2[Mes],0))*F13) -> 31982.547 | G15: =+(INDEX(Tabla2[Lubricantes],MATCH(G19,Tabla2[Mes],0))*G13) -> 38669.531 | H15: =+(INDEX(Tabla2[Lubricantes],MATCH(H19,Tabla2[Mes],0))*H13) -> 35833.627 | I15: =+(INDEX(Tabla2[Lubricantes],MATCH(I19,Tabla2[Mes],0))*I13) -> 24626.901 | J15: =+(INDEX(Tabla2[Lubricantes],MATCH(J19,Tabla2[Mes],0))*J13) -> 6670.6701 | ... N15: =+(INDEX(Tabla2[Lubricantes],MATCH(N19,Tabla2[Mes],0))*N13) -> 48484.61
A16: Combustible Pesos | B16: =SUM(C16:N16) -> 2303452.7 | C16: =+(C9*INDEX(Tabla2[Combustible],MATCH(C19,Tabla2[Mes],0)))+(C13*INDEX(Tabla2[Lubricantes],MATCH(C19,Tabla2[Mes],0))) -> 44948.792 | D16: =+(D9*INDEX(Tabla2[Combustible],MATCH(D19,Tabla2[Mes],0)))+(D13*INDEX(Tabla2[Lubricantes],MATCH(D19,Tabla2[Mes],0))) -> 44534.013 | E16: =+(E9*INDEX(Tabla2[Combustible],MATCH(E19,Tabla2[Mes],0)))+(E13*INDEX(Tabla2[Lubricantes],MATCH(E19,Tabla2[Mes],0))) -> 39573.927 | F16: =+(F9*INDEX(Tabla2[Combustible],MATCH(F19,Tabla2[Mes],0)))+(F13*INDEX(Tabla2[Lubricantes],MATCH(F19,Tabla2[Mes],0))) -> 299773.78 | G16: =+(G9*INDEX(Tabla2[Combustible],MATCH(G19,Tabla2[Mes],0)))+(G13*INDEX(Tabla2[Lubricantes],MATCH(G19,Tabla2[Mes],0))) -> 358723.27 | H16: =+(H9*INDEX(Tabla2[Combustible],MATCH(H19,Tabla2[Mes],0)))+(H13*INDEX(Tabla2[Lubricantes],MATCH(H19,Tabla2[Mes],0))) -> 335870.12 | I16: =+(I9*INDEX(Tabla2[Combustible],MATCH(I19,Tabla2[Mes],0)))+(I13*INDEX(Tabla2[Lubricantes],MATCH(I19,Tabla2[Mes],0))) -> 230829 | J16: =+(J9*INDEX(Tabla2[Combustible],MATCH(J19,Tabla2[Mes],0)))+(J13*INDEX(Tabla2[Lubricantes],MATCH(J19,Tabla2[Mes],0))) -> 61244.187 | ... N16: =+(N9*INDEX(Tabla2[Combustible],MATCH(N19,Tabla2[Mes],0)))+(N13*INDEX(Tabla2[Lubricantes],MATCH(N19,Tabla2[Mes],0))) -> 391625.54
A17: Combustibles USD | B17: =SUM(C17:N17) -> 1918.5062 | C17: =+C16/INDEX(Tabla2[TC],MATCH(C19,Tabla2[Mes],0)) -> 39.883578 | D17: =+D16/INDEX(Tabla2[TC],MATCH(D19,Tabla2[Mes],0)) -> 39.124297 | E17: =+E16/INDEX(Tabla2[TC],MATCH(E19,Tabla2[Mes],0)) -> 34.422506 | F17: =+F16/INDEX(Tabla2[TC],MATCH(F19,Tabla2[Mes],0)) -> 258.1699 | G17: =+G16/INDEX(Tabla2[TC],MATCH(G19,Tabla2[Mes],0)) -> 305.87933 | H17: =+H16/INDEX(Tabla2[TC],MATCH(H19,Tabla2[Mes],0)) -> 283.55714 | I17: =+I16/INDEX(Tabla2[TC],MATCH(I19,Tabla2[Mes],0)) -> 192.94708 | J17: =+J16/INDEX(Tabla2[TC],MATCH(J19,Tabla2[Mes],0)) -> 50.686388 | ... N17: =+N16/INDEX(Tabla2[TC],MATCH(N19,Tabla2[Mes],0)) -> 311.46695 | P17: =SUM(C17:N17)/SUMIFS(TablaGeneral[Has],TablaGeneral[Finca],A18) -> 71.639516
A18: Puente Alto | B18: Jorn | C18: 0.13761016 | D18: 0.11847751 | E18: 0 | F18: 0 | G18: 0.0095663265 | H18: 0 | I18: 0 | J18: 0.0031887755 | K18: 0.07903824 | L18: 0.25998661 | M18: 0.24164543 | N18: 0.15036527
A19: Flame | B19: 707.19489 | C19: Mayo | D19: Junio | E19: Julio | F19: Agosto | G19: Septiembre | H19: Octubre | I19: Noviembre | J19: Diciembre | K19: Enero | L19: Febrero | M19: Marzo | N19: Abril
A20: Tractorista Subsolado | B20: 8.6508144 | F20: =+B20 -> 8.6508144
A21: Tractorista Triturado de sarmiento | B21: 3.7847313 | F21: =+B21 -> 3.7847313
A22: Tractorista Cincelado | B22: 1.6220996 | F22: =+B22 -> 1.6220996
A23: Tractorista Rastra | B23: 34.062582 | G23: =+B23/2 -> 17.031291 | N23: =+B23/2 -> 17.031291
A24: Tractor Atomizadora | B24: 32.530667 | H24: =+B24*0.45 -> 14.6388 | I24: =+B24*0.275 -> 8.9459333 | L24: =+B24*0.275 -> 8.9459333
A25: Tractor Herbicida | B25: 4.0555186 | H25: =+B25/4 -> 1.0138797 | I25: =+B25/4 -> 1.0138797 | J25: =+B25/4 -> 1.0138797 | L25: =+B25/4 -> 1.0138797
A26: Poda | B26: 182.81333 | D26: =+B26/3 -> 60.937778 | E26: =+B26/3 -> 60.937778 | F26: =+B26/3 -> 60.937778
A27: Atada | B27: 121.87556 | D27: =+B27/3 -> 40.625185 | E27: =+B27/3 -> 40.625185 | F27: =+B27/3 -> 40.625185
A28: Acomodo de brotes | B28: 81.326667 | I28: =+B28 -> 81.326667
A29: Desbrote de troncos | B29: 187.67692 | H29: =+B29/2 -> 93.838462 | J29: =+B29/2 -> 93.838462
A30: Raleo de Racimos | B30: 0 | I30: =+B30 -> 0
A31: Desniete Deshoje | B31: 0
A32: Desbrote con criterio de Poda | B32: 48.796 | H32: =+B32 -> 48.796
A33: Arizul | B33: 293.85887 | C33: =+SUM(C20:C32) -> 0 | D33: =+SUM(D20:D32) -> 101.56296 | E33: =+SUM(E20:E32) -> 101.56296 | F33: =+SUM(F20:F32) -> 115.62061 | G33: =+SUM(G20:G32) -> 17.031291 | H33: =+SUM(H20:H32) -> 158.28714 | I33: =+SUM(I20:I32) -> 91.28648 | J33: =+SUM(J20:J32) -> 94.852341 | ... N33: =+SUM(N20:N32) -> 17.031291
A34: Tractorista Subsolado | B34: 4.0452964 | F34: =+B34 -> 4.0452964
A35: Tractorista Triturado de sarmiento | B35: 1.7698172 | F35: =+B35 -> 1.7698172
A36: Tractorista Cincelado | B36: 0.75852669 | F36: =+B36 -> 0.75852669
A37: Tractorista Rastra | B37: 15.928355 | G37: =+B37/2 -> 7.9641773 | N37: =+B37/2 -> 7.9641773
A38: Tractor Atomizadora | B38: 15.212 | H38: =+B38*0.45 -> 6.8454 | I38: =+B38*0.275 -> 4.1833 | L38: =+B38*0.275 -> 4.1833
A39: Tractor Herbicida | B39: 1.8964428 | H39: =+B39/4 -> 0.4741107 | I39: =+B39/4 -> 0.4741107 | J39: =+B39/4 -> 0.4741107 | L39: =+B39/4 -> 0.4741107
A40: Poda | B40: 63.383333 | D40: =+B40/3 -> 21.127778 | E40: =+B40/3 -> 21.127778 | F40: =+B40/3 -> 21.127778
...

Sheet Visualización Jornales LCH
A1: Jornal Presupuestado | B1: $ | C1: =+INDEX(Tabla2[Precio Jornal],MATCH(C$19,Tabla2[Mes],0)) -> 19319.2 | D1: =+INDEX(Tabla2[Precio Jornal],MATCH(D$19,Tabla2[Mes],0)) -> 19646 | E1: =+INDEX(Tabla2[Precio Jornal],MATCH(E$19,Tabla2[Mes],0)) -> 19976.6 | F1: =+INDEX(Tabla2[Precio Jornal],MATCH(F$19,Tabla2[Mes],0)) -> 20312.9 | G1: =+INDEX(Tabla2[Precio Jornal],MATCH(G$19,Tabla2[Mes],0)) -> 20654.9 | H1: =+INDEX(Tabla2[Precio Jornal],MATCH(H$19,Tabla2[Mes],0)) -> 21002.6 | I1: =+INDEX(Tabla2[Precio Jornal],MATCH(I$19,Tabla2[Mes],0)) -> 21357.9 | J1: =+INDEX(Tabla2[Precio Jornal],MATCH(J$19,Tabla2[Mes],0)) -> 21717 | ... N1: =+INDEX(Tabla2[Precio Jornal],MATCH(N$19,Tabla2[Mes],0)) -> 23218
A2: Días Laborales | C2: 23.5 | D2: 20.5 | E2: 24 | F2: 24 | G2: 23 | H2: 24.5 | I2: 22.5 | J2: 23 | K2: 24 | L2: 20.5 | M2: 23 | N2: 22
A3: Jornales Disponibles PA | B3: 3 | C3: =+$B3*C2 -> 70.5 | D3: =+$B3*D2 -> 61.5 | E3: =+$B3*E2 -> 72 | F3: =+$B3*F2 -> 72 | G3: =+$B3*G2 -> 69 | H3: =+$B3*H2 -> 73.5 | I3: =+$B3*I2 -> 67.5 | J3: =+$B3*J2 -> 69 | ... N3: =+$B3*N2 -> 66 | O3: cosecha | P3: secado | Q3: gral | R3: Jorn/Has
A4: Jornales Cosecha | B4: =+SUMIF(TablaGeneral[Finca],"La Chimbera",TablaGeneral[Resumen Jornales totales de Cosecha]) -> 283.04332 | K4: =+B4*0.2 -> 56.608664 | L4: =+B4*0.4 -> 113.21733 | M4: =+B4*0.4 -> 113.21733 | O4: =SUM(C4:N4) -> 283.04332 | P4: =SUM(C5:N5) -> 315.00946 | Q4: =+O85 -> 2516.6226 | R4: =+(O4+P4+Q4)/SUMIFS(TablaGeneral[Has],TablaGeneral[Finca],A18) -> 77.287231
A5: Jornales Secado | B5: =+SUMIFS(TablaGeneral[Resumen Jornales totales de Secado],TablaGeneral[Finca],"La Chimbera") -> 315.0478 | C5: =+$B5*C18 -> 43.353779 | D5: =+$B5*D18 -> 37.326079 | E5: =+$B5*E18 -> 0 | F5: =+$B5*F18 -> 0 | G5: =+$B5*G18 -> 3.0138501 | H5: =+$B5*H18 -> 0 | I5: =+$B5*I18 -> 0 | J5: =+$B5*J18 -> 1.0046167 | ... N5: =+$B5*N18 -> 47.372246 | Q5: =+Q4/40 -> 62.915566
A6: Jornales a contratar | B6: =SUM(C6:N6) -> 2291.1754 | C6: =+(C5+C4+C85)-C3 -> 165.54062 | D6: =+(D5+D4+D85)-D3 -> 267.97623 | E6: =+(E5+E4+E85)-E3 -> 218.84974 | F6: =+(F5+F4+F85)-F3 -> 261.63731 | G6: =+(G5+G4+G85)-G3 -> 68.725773 | H6: =+(H5+H4+H85)-H3 -> 236.30147 | I6: =+(I5+I4+I85)-I3 -> 347.79934 | J6: =+(J5+J4+J85)-J3 -> 265.64768 | ... N6: =+(N5+N4+N85)-N3 -> 23.501866
A7: Contratados LCH $ | B7: =SUM(C7:N7) -> 48106736 | C7: =+C6*C1 -> 3198112.4 | D7: =+D6*D1 -> 5264661.1 | E7: =+E6*E1 -> 4371873.7 | F7: =+F6*F1 -> 5314612.5 | G7: =+G6*G1 -> 1419524 | H7: =+H6*H1 -> 4962945.3 | I7: =+I6*I1 -> 7428263.6 | J7: =+J6*J1 -> 5769070.8 | ... N7: =+N6*N1 -> 545666.33 | P7: USD/Has
A8: Contratados LCH USD | B8: =SUM(C8:N8) -> 40608.532 | C8: =+C7/INDEX(Tabla2[TC],MATCH(C19,Tabla2[Mes],0)) -> 2837.7218 | D8: =+D7/INDEX(Tabla2[TC],MATCH(D19,Tabla2[Mes],0)) -> 4625.1426 | E8: =+E7/INDEX(Tabla2[TC],MATCH(E19,Tabla2[Mes],0)) -> 3802.7777 | F8: =+F7/INDEX(Tabla2[TC],MATCH(F19,Tabla2[Mes],0)) -> 4577.028 | G8: =+G7/INDEX(Tabla2[TC],MATCH(G19,Tabla2[Mes],0)) -> 1210.4123 | H8: =+H7/INDEX(Tabla2[TC],MATCH(H19,Tabla2[Mes],0)) -> 4189.9487 | I8: =+I7/INDEX(Tabla2[TC],MATCH(I19,Tabla2[Mes],0)) -> 6209.1928 | J8: =+J7/INDEX(Tabla2[TC],MATCH(J19,Tabla2[Mes],0)) -> 4774.5488 | ... N8: =+N7/INDEX(Tabla2[TC],MATCH(N19,Tabla2[Mes],0)) -> 433.97841 | P8: =+B8/SUMIFS(TablaGeneral[Has],TablaGeneral[Finca],A18) -> 1007.6559
A9: Combustible Litros Gen | B9: =SUM(C9:N9) -> 2262.2738 | C9: =+(SUM(C20:C25,C34:C39,C48:C53,C74)*13) -> 48.772585 | D9: =+(SUM(D20:D25,D34:D39,D48:D53,D74)*13) -> 48.772585 | E9: =+(SUM(E20:E25,E34:E39,E48:E53,E74)*13) -> 48.772585 | F9: =+(SUM(F20:F25,F34:F39,F48:F53,F74)*13) -> 295.61348 | G9: =+(SUM(G20:G25,G34:G39,G48:G53,G74)*13) -> 398.23732 | H9: =+(SUM(H20:H25,H34:H39,H48:H53,H74)*13) -> 348.16874 | I9: =+(SUM(I20:I25,I34:I39,I48:I53,I74)*13) -> 384.17306 | J9: =+(SUM(J20:J25,J34:J39,J48:J53,J74)*13) -> 126.77259 | ... N9: =+(SUM(N20:N25,N34:N39,N48:N53,N74)*13) -> 81.272585
A10: Combustible Litros Sec | B10: =SUM(C10:N10) -> 1207.2827 | C10: =+SUM(TablaGeneral[Tractor Volcado de bins],TablaGeneral[Tractor Cincelado de piedras],TablaGeneral[Tractor Carga de pasa],TablaGeneral[Tractor Descarga y carga de bines con tracto elevador],TablaGeneral[Descarga y carga de bines con Autoelevador])*10*C18*0.28 -> 166.15459 | D10: =+SUM(TablaGeneral[Tractor Volcado de bins],TablaGeneral[Tractor Cincelado de piedras],TablaGeneral[Tractor Carga de pasa],TablaGeneral[Tractor Descarga y carga de bines con tracto elevador],TablaGeneral[Descarga y carga de bines con Autoelevador])*10*D18*0.28 -> 143.05326 | E10: =+SUM(TablaGeneral[Tractor Volcado de bins],TablaGeneral[Tractor Cincelado de piedras],TablaGeneral[Tractor Carga de pasa],TablaGeneral[Tractor Descarga y carga de bines con tracto elevador],TablaGeneral[Descarga y carga de bines con Autoelevador])*10*E18*0.28 -> 0 | F10: =+SUM(TablaGeneral[Tractor Volcado de bins],TablaGeneral[Tractor Cincelado de piedras],TablaGeneral[Tractor Carga de pasa],TablaGeneral[Tractor Descarga y carga de bines con tracto elevador],TablaGeneral[Descarga y carga de bines con Autoelevador])*10*F18*0.28 -> 0 | G10: =+SUM(TablaGeneral[Tractor Volcado de bins],TablaGeneral[Tractor Cincelado de piedras],TablaGeneral[Tractor Carga de pasa],TablaGeneral[Tractor Descarga y carga de bines con tracto elevador],TablaGeneral[Descarga y carga de bines con Autoelevador])*10*G18*0.28 -> 11.550666 | H10: =+SUM(TablaGeneral[Tractor Volcado de bins],TablaGeneral[Tractor Cincelado de piedras],TablaGeneral[Tractor Carga de pasa],TablaGeneral[Tractor Descarga y carga de bines con tracto elevador],TablaGeneral[Descarga y carga de bines con Autoelevador])*10*H18*0.28 -> 0 | I10: =+SUM(TablaGeneral[Tractor Volcado de bins],TablaGeneral[Tractor Cincelado de piedras],TablaGeneral[Tractor Carga de pasa],TablaGeneral[Tractor Descarga y carga de bines con tracto elevador],TablaGeneral[Descarga y carga de bines con Autoelevador])*10*I18*0.28 -> 0 | J10: =+SUM(TablaGeneral[Tractor Volcado de bins],TablaGeneral[Tractor Cincelado de piedras],TablaGeneral[Tractor Carga de pasa],TablaGeneral[Tractor Descarga y carga de bines con tracto elevador],TablaGeneral[Descarga y carga de bines con Autoelevador])*10*J18*0.28 -> 3.850222 | ... N10: =+SUM(TablaGeneral[Tractor Volcado de bins],TablaGeneral[Tractor Cincelado de piedras],TablaGeneral[Tractor Carga de pasa],TablaGeneral[Tractor Descarga y carga de bines con tracto elevador],TablaGeneral[Descarga y carga de bines con Autoelevador])*10*N18*0.28 -> 181.55548
A11: Combustible Litros Cos | B11: =SUM(C11:N11) -> 2150.1046 | K11: =+(SUMIFS(TablaGeneral[Tracto elevador],TablaGeneral[Finca],A18)+SUMIFS(TablaGeneral[Tractor con uñas],TablaGeneral[Finca],A18)+SUMIFS(TablaGeneral[Tractor con acoplado],TablaGeneral[Finca],A18))*0.2*10 -> 430.02092 | L11: =+(SUMIFS(TablaGeneral[Tracto elevador],TablaGeneral[Finca],A18)+SUMIFS(TablaGeneral[Tractor con uñas],TablaGeneral[Finca],A18)+SUMIFS(TablaGeneral[Tractor con acoplado],TablaGeneral[Finca],A18))*0.4*10 -> 860.04183 | M11: =+(SUMIFS(TablaGeneral[Tracto elevador],TablaGeneral[Finca],A18)+SUMIFS(TablaGeneral[Tractor con uñas],TablaGeneral[Finca],A18)+SUMIFS(TablaGeneral[Tractor con acoplado],TablaGeneral[Finca],A18))*0.4*10 -> 860.04183
A12: Combustible Litros Tot | B12: =SUM(C12:N12) -> 5619.661 | C12: =SUM(C9:C11) -> 214.92717 | D12: =SUM(D9:D11) -> 191.82584 | E12: =SUM(E9:E11) -> 48.772585 | F12: =SUM(F9:F11) -> 295.61348 | G12: =SUM(G9:G11) -> 409.78799 | H12: =SUM(H9:H11) -> 348.16874 | I12: =SUM(I9:I11) -> 384.17306 | J12: =SUM(J9:J11) -> 130.62281 | ... N12: =SUM(N9:N11) -> 262.82806
A13: Lubricantes Litros Totales | B13: =SUM(C13:N13) -> 121.75932 | C13: =+(C12/100)+(C12/150)+(C12/200) -> 4.6567554 | D13: =+(D12/100)+(D12/150)+(D12/200) -> 4.1562265 | E13: =+(E12/100)+(E12/150)+(E12/200) -> 1.0567393 | F13: =+(F12/100)+(F12/150)+(F12/200) -> 6.4049587 | G13: =+(G12/100)+(G12/150)+(G12/200) -> 8.8787398 | H13: =+(H12/100)+(H12/150)+(H12/200) -> 7.5436561 | I13: =+(I12/100)+(I12/150)+(I12/200) -> 8.3237497 | J13: =+(J12/100)+(J12/150)+(J12/200) -> 2.8301608 | ... N13: =+(N12/100)+(N12/150)+(N12/200) -> 5.694608
A14: Combustible USD | B14: =SUM(C14:N14) -> 6987115.3 | C14: =+(INDEX(Tabla2[Combustible],MATCH(C19,Tabla2[Mes],0))*C12) -> 248278.5 | D14: =+(INDEX(Tabla2[Combustible],MATCH(D19,Tabla2[Mes],0))*D12) -> 223808.34 | E14: =+(INDEX(Tabla2[Combustible],MATCH(E19,Tabla2[Mes],0))*E12) -> 57473.323 | F14: =+(INDEX(Tabla2[Combustible],MATCH(F19,Tabla2[Mes],0))*F12) -> 351832.65 | G14: =+(INDEX(Tabla2[Combustible],MATCH(G19,Tabla2[Mes],0))*G12) -> 492597.84 | H14: =+(INDEX(Tabla2[Combustible],MATCH(H19,Tabla2[Mes],0))*H12) -> 422711.86 | I14: =+(INDEX(Tabla2[Combustible],MATCH(I19,Tabla2[Mes],0))*I12) -> 471088.97 | J14: =+(INDEX(Tabla2[Combustible],MATCH(J19,Tabla2[Mes],0))*J12) -> 161776.86 | ... N14: =+(INDEX(Tabla2[Combustible],MATCH(N19,Tabla2[Mes],0))*N12) -> 338730.75
A15: Lubricantes USD | B15: =SUM(C15:N15) -> 834477.43 | C15: =+(INDEX(Tabla2[Lubricantes],MATCH(C19,Tabla2[Mes],0))*C13) -> 29652.123 | D15: =+(INDEX(Tabla2[Lubricantes],MATCH(D19,Tabla2[Mes],0))*D13) -> 26729.63 | E15: =+(INDEX(Tabla2[Lubricantes],MATCH(E19,Tabla2[Mes],0))*E13) -> 6864.0903 | F15: =+(INDEX(Tabla2[Lubricantes],MATCH(F19,Tabla2[Mes],0))*F13) -> 42019.688 | G15: =+(INDEX(Tabla2[Lubricantes],MATCH(G19,Tabla2[Mes],0))*G13) -> 58831.4 | H15: =+(INDEX(Tabla2[Lubricantes],MATCH(H19,Tabla2[Mes],0))*H13) -> 50484.855 | I15: =+(INDEX(Tabla2[Lubricantes],MATCH(I19,Tabla2[Mes],0))*I13) -> 56262.577 | J15: =+(INDEX(Tabla2[Lubricantes],MATCH(J19,Tabla2[Mes],0))*J13) -> 19321.155 | ... N15: =+(INDEX(Tabla2[Lubricantes],MATCH(N19,Tabla2[Mes],0))*N13) -> 40454.916
A16: Combustible Pesos | B16: =SUM(C16:N16) -> 3599902.1 | C16: =+(C9*INDEX(Tabla2[Combustible],MATCH(C19,Tabla2[Mes],0)))+(C13*INDEX(Tabla2[Lubricantes],MATCH(C19,Tabla2[Mes],0))) -> 85992.994 | D16: =+(D9*INDEX(Tabla2[Combustible],MATCH(D19,Tabla2[Mes],0)))+(D13*INDEX(Tabla2[Lubricantes],MATCH(D19,Tabla2[Mes],0))) -> 83633.91 | E16: =+(E9*INDEX(Tabla2[Combustible],MATCH(E19,Tabla2[Mes],0)))+(E13*INDEX(Tabla2[Lubricantes],MATCH(E19,Tabla2[Mes],0))) -> 64337.413 | F16: =+(F9*INDEX(Tabla2[Combustible],MATCH(F19,Tabla2[Mes],0)))+(F13*INDEX(Tabla2[Lubricantes],MATCH(F19,Tabla2[Mes],0))) -> 393852.34 | G16: =+(G9*INDEX(Tabla2[Combustible],MATCH(G19,Tabla2[Mes],0)))+(G13*INDEX(Tabla2[Lubricantes],MATCH(G19,Tabla2[Mes],0))) -> 537544.42 | H16: =+(H9*INDEX(Tabla2[Combustible],MATCH(H19,Tabla2[Mes],0)))+(H13*INDEX(Tabla2[Lubricantes],MATCH(H19,Tabla2[Mes],0))) -> 473196.71 | I16: =+(I9*INDEX(Tabla2[Combustible],MATCH(I19,Tabla2[Mes],0)))+(I13*INDEX(Tabla2[Lubricantes],MATCH(I19,Tabla2[Mes],0))) -> 527351.54 | J16: =+(J9*INDEX(Tabla2[Combustible],MATCH(J19,Tabla2[Mes],0)))+(J13*INDEX(Tabla2[Lubricantes],MATCH(J19,Tabla2[Mes],0))) -> 176329.5 | ... N16: =+(N9*INDEX(Tabla2[Combustible],MATCH(N19,Tabla2[Mes],0)))+(N13*INDEX(Tabla2[Lubricantes],MATCH(N19,Tabla2[Mes],0))) -> 145198.39
A17: Combustibles USD | B17: =SUM(C17:N17) -> 3006.7708 | C17: =+C16/INDEX(Tabla2[TC],MATCH(C19,Tabla2[Mes],0)) -> 76.302568 | D17: =+D16/INDEX(Tabla2[TC],MATCH(D19,Tabla2[Mes],0)) -> 73.47458 | E17: =+E16/INDEX(Tabla2[TC],MATCH(E19,Tabla2[Mes],0)) -> 55.962477 | F17: =+F16/INDEX(Tabla2[TC],MATCH(F19,Tabla2[Mes],0)) -> 339.19183 | G17: =+G16/INDEX(Tabla2[TC],MATCH(G19,Tabla2[Mes],0)) -> 458.35814 | H17: =+H16/INDEX(Tabla2[TC],MATCH(H19,Tabla2[Mes],0)) -> 399.49462 | I17: =+I16/INDEX(Tabla2[TC],MATCH(I19,Tabla2[Mes],0)) -> 440.80657 | J17: =+J16/INDEX(Tabla2[TC],MATCH(J19,Tabla2[Mes],0)) -> 145.93231 | ... N17: =+N16/INDEX(Tabla2[TC],MATCH(N19,Tabla2[Mes],0)) -> 115.47893 | P17: =SUM(C17:N17)/SUMIFS(TablaGeneral[Has],TablaGeneral[Finca],A18) -> 74.609697
A18: La Chimbera | B18: Jorn | C18: 0.13761016 | D18: 0.11847751 | E18: 0 | F18: 0 | G18: 0.0095663265 | H18: 0 | I18: 0 | J18: 0.0031887755 | K18: 0.07903824 | L18: 0.25998661 | M18: 0.24164543 | N18: 0.15036527
A19: Flame | B19: 893.41487 | C19: Mayo | D19: Junio | E19: Julio | F19: Agosto | G19: Septiembre | H19: Octubre | I19: Noviembre | J19: Diciembre | K19: Enero | L19: Febrero | M19: Marzo | N19: Abril
A20: Tractorista Subsolado | B20: 9.0123167 | G20: =+B20 -> 9.0123167
A21: Tractorista Triturado de sarmiento | B21: 2.3718453 | F21: =+B21 -> 2.3718453
A22: Tractorista Cincelado | B22: 1.8982088 | F22: =+B22 -> 1.8982088
A23: Tractorista Rastra | B23: 2.3718453 | G23: =+B23/2 -> 1.1859227 | N23: =+B23/2 -> 1.1859227
A24: Tractor Atomizadora | B24: 34.154636 | G24: =+B24*0.45 -> 15.369586 | I24: =+B24*0.275 -> 9.3925249 | L24: =+B24*0.275 -> 9.3925249
A25: Tractor Herbicida | B25: 11.384858 | H25: =+B25/4 -> 2.8462144 | I25: =+B25/4 -> 2.8462144 | J25: =+B25/4 -> 2.8462144 | L25: =+B25/4 -> 2.8462144
A26: Poda | B26: 236.4 | D26: =+B26/3 -> 78.8 | E26: =+B26/3 -> 78.8 | F26: =+B26/3 -> 78.8
A27: Atada | B27: 157.6 | D27: =+B27/3 -> 52.533333 | E27: =+B27/3 -> 52.533333 | F27: =+B27/3 -> 52.533333
A28: Acomodo de brotes | B28: 61.464 | I28: =+B28 -> 61.464
A29: Desbrote de troncos | B29: 151.38916 | G29: =+B29/2/2 -> 37.847291 | H29: =+B29/2/2 -> 37.847291 | J29: =+B29/2 -> 75.694581
A30: Raleo de Racimos | B30: 102.44 | I30: =+B30 -> 102.44
A31: Desniete Deshoje | B31: 61.464 | J31: =+B31 -> 61.464
A32: Desbrote con criterio de Poda | B32: 61.464 | H32: =+B32 -> 61.464
A33: Arizul | B33: 518.38423 | C33: =+SUM(C20:C32) -> 0 | D33: =+SUM(D20:D32) -> 131.33333 | E33: =+SUM(E20:E32) -> 131.33333 | F33: =+SUM(F20:F32) -> 135.60339 | G33: =+SUM(G20:G32) -> 63.415116 | H33: =+SUM(H20:H32) -> 102.15751 | I33: =+SUM(I20:I32) -> 176.14274 | J33: =+SUM(J20:J32) -> 140.0048 | ... N33: =+SUM(N20:N32) -> 1.1859227
A34: Tractorista Subsolado | B34: 5.3560117 | F34: =+B34 -> 5.3560117
A35: Tractorista Triturado de sarmiento | B35: 1.4095856 | F35: =+B35 -> 1.4095856
A36: Tractorista Cincelado | B36: 1.1281038 | F36: =+B36 -> 1.1281038
A37: Tractorista Rastra | B37: 1.4095856 | G37: =+B37/2 -> 0.70479278 | N37: =+B37/2 -> 0.70479278
A38: Tractor Atomizadora | B38: 20.29807 | H38: =+B38*0.45 -> 9.1341313 | I38: =+B38*0.275 -> 5.5819691 | L38: =+B38*0.275 -> 5.5819691
A39: Tractor Herbicida | B39: 6.7660107 | H39: =+B39/4 -> 1.6915027 | I39: =+B39/4 -> 1.6915027 | J39: =+B39/4 -> 1.6915027 | L39: =+B39/4 -> 1.6915027
A40: Poda | B40: 132.94945 | D40: =+B40/3 -> 44.316484 | E40: =+B40/3 -> 44.316484 | F40: =+B40/3 -> 44.316484
...

Sheet Visualización Jornales EE
A1: Jornal Presupuestado | B1: $ | C1: =+INDEX(Tabla2[Precio Jornal],MATCH(C$25,Tabla2[Mes],0)) -> 19319.2 | D1: =+INDEX(Tabla2[Precio Jornal],MATCH(D$25,Tabla2[Mes],0)) -> 19646 | E1: =+INDEX(Tabla2[Precio Jornal],MATCH(E$25,Tabla2[Mes],0)) -> 19976.6 | F1: =+INDEX(Tabla2[Precio Jornal],MATCH(F$25,Tabla2[Mes],0)) -> 20312.9 | G1: =+INDEX(Tabla2[Precio Jornal],MATCH(G$25,Tabla2[Mes],0)) -> 20654.9 | H1: =+INDEX(Tabla2[Precio Jornal],MATCH(H$25,Tabla2[Mes],0)) -> 21002.6 | I1: =+INDEX(Tabla2[Precio Jornal],MATCH(I$25,Tabla2[Mes],0)) -> 21357.9 | J1: =+INDEX(Tabla2[Precio Jornal],MATCH(J$25,Tabla2[Mes],0)) -> 21717 | ... N1: =+INDEX(Tabla2[Precio Jornal],MATCH(N$25,Tabla2[Mes],0)) -> 23218
A2: Días Laborales | C2: 23.5 | D2: 20.5 | E2: 24 | F2: 24 | G2: 23 | H2: 24.5 | I2: 22.5 | J2: 23 | K2: 24 | L2: 20.5 | M2: 23 | N2: 22
A3: Jornales Disponibles EE | B3: =23 -> 23 | C3: =+$B3*C2 -> 540.5 | D3: =+$B3*D2 -> 471.5 | E3: =+$B3*E2 -> 552 | F3: =+$B3*F2 -> 552 | G3: =+$B3*G2 -> 529 | H3: =+$B3*H2 -> 563.5 | I3: =+$B3*I2 -> 517.5 | J3: =+$B3*J2 -> 529 | ... N3: =+$B3*N2 -> 506
A4: Jornales Cosecha | B4: =+SUMIF(TablaGeneral[Finca],"El Espejo I",TablaGeneral[Resumen Jornales totales de Cosecha])+SUMIF(TablaGeneral[Finca],"El Espejo II",TablaGeneral[Resumen Jornales totales de Cosecha])+SUMIF(TablaGeneral[Finca],"El Espejo III",TablaGeneral[Resumen Jornales totales de Cosecha]) -> 936.11198 | K4: =+B4*0.2 -> 187.2224 | L4: =+B4*0.4 -> 374.44479 | M4: =+B4*0.4 -> 374.44479
A5: Jornales Secado | B5: =+SUMIFS(TablaGeneral[Resumen Jornales totales de Secado],TablaGeneral[Finca],"Camino truncado")*0.75 -> 850.03374 | C5: =+$B5*C24 -> 116.97328 | D5: =+$B5*D24 -> 100.70988 | E5: =+$B5*E24 -> 0 | F5: =+$B5*F24 -> 0 | G5: =+$B5*G24 -> 8.1317003 | H5: =+$B5*H24 -> 0 | I5: =+$B5*I24 -> 0 | J5: =+$B5*J24 -> 2.7105668 | ... N5: =+$B5*N24 -> 127.81555
A6: Jornales a contratar | B6: =SUM(C6:N6) -> 19936.788 | C6: =+(C127+C4+C5)-C3 -> 268.40932 | D6: =+D127+D4+D5-D3 -> 1968.5862 | E6: =+E127+E4+E5-E3 -> 1914.8032 | F6: =+F127+F4+F5-F3 -> 2303.1977 | G6: =+G127+G4+G5-G3 -> 1662.911 | H6: =+H127+H4+H5-H3 -> 1862.7863 | I6: =+I127+I4+I5-I3 -> 2963.5331 | J6: =+J127+J4+J5-J3 -> 3129.1805 | K6: =+K127+K4+K5-K3 -> 405.26267 | ... N6: =+N127+N4+N5-N3 -> 615.97233
A7: Contratados EE $ | B7: =SUM(C7:N7) -> 4.2123719e+08 | C7: =+C6*C1 -> 5185453.4 | D7: =+D6*D1 -> 38674844 | E7: =+E6*E1 -> 38251258 | F7: =+F6*F1 -> 46784624 | G7: =+G6*G1 -> 34347259 | H7: =+H6*H1 -> 39123356 | I7: =+I6*I1 -> 63294844 | J7: =+J6*J1 -> 67956414 | ... N7: =+N6*N1 -> 14301646 | P7: USD/Has
A8: Contratados EE USD | B8: =SUM(C8:N8) -> 354272.23 | C8: =+C7/INDEX(Tabla2[TC],MATCH(C25,Tabla2[Mes],0)) -> 4601.1121 | D8: =+D7/INDEX(Tabla2[TC],MATCH(D25,Tabla2[Mes],0)) -> 33976.863 | E8: =+E7/INDEX(Tabla2[TC],MATCH(E25,Tabla2[Mes],0)) -> 33272.012 | F8: =+F7/INDEX(Tabla2[TC],MATCH(F25,Tabla2[Mes],0)) -> 40291.655 | G8: =+G7/INDEX(Tabla2[TC],MATCH(G25,Tabla2[Mes],0)) -> 29287.525 | H8: =+H7/INDEX(Tabla2[TC],MATCH(H25,Tabla2[Mes],0)) -> 33029.753 | I8: =+I7/INDEX(Tabla2[TC],MATCH(I25,Tabla2[Mes],0)) -> 52907.37 | J8: =+J7/INDEX(Tabla2[TC],MATCH(J25,Tabla2[Mes],0)) -> 56241.503 | ... N8: =+N7/INDEX(Tabla2[TC],MATCH(N25,Tabla2[Mes],0)) -> 11374.36 | P8: =+B8/(SUMIFS(TablaGeneral[Has],TablaGeneral[Finca],"El Espejo I")+SUMIFS(TablaGeneral[Has],TablaGeneral[Finca],"El Espejo II")+SUMIFS(TablaGeneral[Has],TablaGeneral[Finca],"El Espejo III")) -> 1422.4944
A9: Contratados EE I y II $ | B9: =SUM(C9:N9) -> 2.9149613e+08 | C9: =+C7*0.692 -> 3588333.7 | D9: =+D7*0.692 -> 26762992 | E9: =+E7*0.692 -> 26469870 | F9: =+F7*0.692 -> 32374960 | G9: =+G7*0.692 -> 23768304 | H9: =+H7*0.692 -> 27073363 | I9: =+I7*0.692 -> 43800032 | J9: =+J7*0.692 -> 47025838 | ... N9: =+N7*0.692 -> 9896738.7 | P9: USD/Has EE I y II
